File: powder_X-ray_diffraction/RbNb2O5F/raw_data/RbNb2O5F.xrdml
<?xml version="1.0" encoding="UTF-8"?>
<xrdMeasurements xmlns="http://www.xrdml.com/XRDMeasurement/1.7" xmlns:xsi="http://www.w3.org/2001/XMLSchema-instance" xsi:schemaLocation="http://www.xrdml.com/XRDMeasurement/1.7 http://www.xrdml.com/XRDMeasurement/1.7/XRDMeasurement.xsd" status="Completed">
	<comment>
		<entry>+1h</entry>
		<entry>Configuration=Reflection-transmission Spinner, Owner=User-1, Creation date=12/01/2015 16:50:12</entry>
		<entry>Goniometer=Theta/Theta; Minimum step size 2Theta:0.0001; Minimum step size Omega:0.0001</entry>
		<entry>Sample stage=Reflection-transmission spinner; Minimum step size Phi:0.1</entry>
		<entry>Diffractometer system=EMPYREAN</entry>
		<entry>Measurement program=C:\PANalytical\Data Collector\Programs\Ouail\lent_1.xrdmp, Identifier={B29941A8-BA7C-4C55-956B-EA990EE29526}</entry>
		<entry>Batch program=C:\PANalytical\Data Collector\Programs\Batch_nuit1.xrdmp, Identifier={1434E619-2D8E-40A4-B2E8-22B1149ABCB4}</entry>
	</comment>
	<sample type="To be analyzed">
		<id>RbNb2O5F</id>
		<name></name>
		<preparedBy></preparedBy>
	</sample>
	<xrdMeasurement measurementType="Scan" status="Completed" sampleMode="Reflection">
		<comment>
			<entry>PHD Lower Level = 4.02 (keV), PHD Upper Level = 12.07 (keV)</entry>
		</comment>
		<usedWavelength intended="K-Alpha 1">
			<kAlpha1 unit="Angstrom">1.5405980</kAlpha1>
			<kAlpha2 unit="Angstrom">1.5444260</kAlpha2>
			<kBeta unit="Angstrom">1.3922500</kBeta>
			<ratioKAlpha2KAlpha1>0.5000</ratioKAlpha2KAlpha1>
		</usedWavelength>
		<incidentBeamPath>
			<radius unit="mm">240.00</radius>
			<xRayTube id="1010048" name="Empyrean Cu LFF HR (9430 033 7310x) DK420743">
				<tension unit="kV">45.0</tension>
				<current unit="mA">30.0</current>
				<anodeMaterial>Cu</anodeMaterial>
				<focus type="Line">
					<length unit="mm">12.0</length>
					<width unit="mm">0.4</width>
					<takeOffAngle unit="deg">6.0</takeOffAngle>
				</focus>
			</xRayTube>
			<sollerSlit id="21010001" name="Soller slits 0.02 rad.">
				<opening unit="rad">0.0200</opening>
			</sollerSlit>
			<mask id="22030010" name="Fixed mask 20 mm">
				<width unit="mm">20.00</width>
			</mask>
			<antiScatterSlit id="22010003" name="Fixed slit 1Â°" xsi:type="fixedAntiScatterSlitType">
				<height unit="mm">1.52</height>
			</antiScatterSlit>
			<divergenceSlit id="22010012" name="Programmable divergence slit" xsi:type="fixedDivergenceSlitType">
				<distanceToSample unit="mm">140.00</distanceToSample>
				<angle unit="deg">0.5</angle>
			</divergenceSlit>
		</incidentBeamPath>
		<sampleMovement xsi:type="spinningSampleMovementType">
			<spinnerRevolutionTime unit="seconds">4.0</spinnerRevolutionTime>
		</sampleMovement>
		<diffractedBeamPath>
			<radius unit="mm">240.00</radius>
			<antiScatterSlit id="22090010" name="AS slit 8.0 mm (PIXcel)" xsi:type="fixedAntiScatterSlitType">
				<height unit="mm">8.00</height>
			</antiScatterSlit>
			<sollerSlit id="21010001" name="Soller slits 0.02 rad.">
				<opening unit="rad">0.0200</opening>
			</sollerSlit>
			<filter id="20010004" name="Beta-filter Nickel">
				<material>Ni</material>
				<thickness unit="mm">0.020</thickness>
			</filter>
			<detector id="7010019" name="PIXcel1D-Medipix3 detector" xsi:type="rtmsDetectorType">
				<phd unit="%">
					<lowerLevel>25.0</lowerLevel>
					<upperLevel>75.0</upperLevel>
				</phd>
				<mode>Scanning</mode>
				<activeLength unit="deg">3.3482</activeLength>
			</detector>
		</diffractedBeamPath>
		<scan appendNumber="0" mode="Continuous" scanAxis="Gonio" status="Completed">
			<header>
				<startTimeStamp>2022-03-04T16:49:48+01:00</startTimeStamp>
				<endTimeStamp>2022-03-04T22:43:55+01:00</endTimeStamp>
				<author>
					<name>User</name>
				</author>
				<source>
					<applicationSoftware version="5.5a">Data Collector</applicationSoftware>
					<instrumentControlSoftware version="8.1b 20190506">EMPYREAN</instrumentControlSoftware>
					<instrumentID>0000000011159748</instrumentID>
				</source>
			</header>
			<dataPoints>
				<positions axis="2Theta" unit="deg">
					<startPosition>5.00656514</startPosition>
					<endPosition>119.98845054</endPosition>
				</positions>
				<positions axis="Omega" unit="deg">
					<startPosition>2.50328257</startPosition>
					<endPosition>59.99422527</endPosition>
				</positions>
				<positions axis="Phi" unit="deg">
					<commonPosition>138.5</commonPosition>
				</positions>
				<commonCountingTime unit="seconds">598.995</commonCountingTime>
				<intensities 27849 27366 27163 27298 27163 27095 26990 26960 26849 26685 26504 26400 26363 26306 26662 26129 26150 26110 26034 26045 25861 25617 25582 25562 25284 25516 25281 25378 25190 25022 24764 24809 24757 24693 24637 24525 24373 24560 24106 24063 24034 24053 23944 23765 23799 23600 23500 23302 23306 22895 23075 22992 22903 22851 22871 22318 22374 22551 22445 22040 22155 22220 21934 21770 21609 21552 21369 21321 21112 21090 21265 20954 20882 20796 20560 20645 20370 20453 20060 19967 20165 19940 19737 19775 19886 19616 19657 19326 19422 18938 19060 19185 19008 18878 18609 18327 18473 18567 18652 18477 18217 18353 18169 18148 18135 17725 17975 17715 17980 17843 17740 17555 17422 17223 17219 17313 17462 17180 16998 16734 16861 16852 16664 16718 16678 16434 16433 16613 16303 16218 16387 16093 16030 16211 16038 15998 15681 15710 15876 15503 15919 15507 15444 15273 15430 15251 15499 15327 15420 15102 15137 15008 14850 15023 14943 14879 14874 14963 14784 14356 14709 14534 14615 14787 14414 14552 14658 14406 14433 14136 14326 14399 14029 14438 14260 14438 14128 14137 14121 14073 14315 14276 14009 13895 14130 14081 13921 14063 13783 13954 13912 13782 13764 13737 13989 13780 13756 13778 14030 13758 13757 14097 13824 13928 13918 13707 13777 13701 13596 13511 13678 13472 13394 13615 13555 13494 13667 13483 13626 13386 13654 13499 13399 13418 13551 13289 13462 13567 13391 13507 13538 13273 13509 13442 13099 13323 13450 13207 13305 13344 13358 13519 13296 13252 13302 13189 13329 13211 13329 13154 13388 13389 13219 13210 13417 13246 13376 13525 13242 13526 13578 13279 13755 13681 13727 13527 13708 13771 13794 13464 13718 13841 13501 13868 13532 13314 13414 13705 13385 13807 13407 13554 13920 13726 13367 13545 13881 13835 13574 13717 13893 13746 13738 13563 13745 13607 13608 13767 13669 13699 13439 13682 13847 13917 13849 13894 13772 13797 13946 13853 13862 13666 13651 13764 13792 13668 13710 13680 13714 13802 13528 13740 13859 13622 13615 13645 13623 13620 13728 14005 13782 13882 13526 13802 13766 13600 13598 13716 13700 13797 13758 13909 13796 14162 14123 14411 14635 14648 14505 14424 14454 14776 14976 15332 15475 16171 17666 19926 24923 34200 49825 68189 88433 103886 104169 82626 50474 28427 19082 16469 15962 15482 15625 15173 14953 14861 14870 14491 14725 14620 14518 14502 14547 14650 14516 14563 14629 14556 14675 14620 14588 14701 14479 14648 14631 14797 14535 14696 14436 14597 14706 14792 14933 14794 14785 14615 14697 14798 14770 14773 14779 14773 14476 14800 14813 14788 14628 14663 14587 14665 14365 14431 14547 14616 14798 14409 14330 14499 14570 14111 14471 14311 14601 14276 14626 14529 14484 14391 14390 14822 14413 14355 14593 14451 14444 14435 14652 14213 14409 14398 14443 14445 14646 14455 14357 14246 14179 14547 14377 14384 14231 14331 14255 14396 14272 14224 14294 14271 14356 14334 14304 14177 14230 13941 14302 14322 14160 13956 14355 14409 14240 14098 14162 14083 14217 14119 14241 14527 14124 14288 14344 14347 13980 14257 14138 14048 13994 14230 14516 14097 14173 14312 14127 14321 14019 14136 14161 14246 14076 14211 14040 14016 13908 14421 14195 13990 13986 13987 14346 14094 14481 14102 14220 14283 14142 13925 13838 14239 13897 13927 14058 14052 14026 14125 13984 14048 14145 14149 14122 14350 14386 14341 14224 14047 14436 14154 14234 14141 13832 14156 13968 14119 14256 13928 14094 14114 14070 14128 14036 14018 13965 13899 14082 14254 14282 14002 14171 14294 14373 14462 14261 14053 14099 13985 14133 14224 14046 14144 14092 14128 13909 14156 14170 14286 14109 14162 14029 14007 13949 14083 14299 14068 14320 13969 14060 13808 14105 14109 14045 14045 14116 14172 14230 14358 14092 13936 13901 14021 14004 13844 14051 13915 13958 14045 13975 13707 13975 13732 13710 14036 13830 13921 14036 13692 14004 13665 13811 13879 14038 14018 13940 13897 13776 14013 14124 14001 13692 13834 13630 13866 13890 13754 13869 13753 13521 13676 13870 13944 13758 13704 13935 13586 13887 13592 13667 14064 13782 13681 13893 13932 13748 13681 13423 13756 13753 13893 13798 13721 13822 13695 13708 13987 13936 13872 13809 13513 13566 13815 13878 13607 13649 13677 14033 14011 13548 13991 13768 13631 13832 14037 13757 13918 13777 13856 14041 14042 14452 14467 14187 13981 13874 14033 13933 14112 14344 14291 14309 14259 14490 14262 14453 14506 14938 15496 16672 19675 25239 33683 44677 55812 59989 54354 40725 30913 21688 16832 15403 15143 14544 14530 14277 14311 14122 13970 14161 13963 14009 13865 13950 13987 13838 13841 13632 13837 13918 13743 13730 13835 13743 13720 13782 13876 13557 13757 13640 13938 13820 13803 13738 13858 13595 13695 14074 13944 13653 13756 13841 13983 13848 13993 14083 14046 14205 14496 14760 14862 14663 14405 14016 13656 13984 13907 13853 13728 13737 13687 13854 13684 13540 13682 13903 13775 13712 13813 13701 13737 13879 13699 13545 13605 13562 13990 13414 13741 13635 13632 13719 13561 13906 14042 13823 13739 13764 13548 13673 13963 13906 14267 14345 14256 14193 13953 13798 13747 13692 13696 13687 13594 13710 13886 13655 13392 13778 13632 13699 13649 13829 13861 13819 13897 14056 14311 14612 14696 15333 15437 15017 15207 15105 15288 15083 15125 15083 14998 15025 15234 15209 15260 15439 15234 15522 15211 15485 15444 15981 15912 16435 16888 17300 18448 18980 20226 21776 24433 29856 41966 68650 120208 199575 301335 378132 376254 282987 203960 145369 71972 35426 26215 22954 20650 19383 18310 17444 16914 16446 16448 16429 16092 16121 16242 16342 16233 15995 15995 15782 15615 15270 15315 15209 15421 15193 15037 15172 15410 15256 15103 15584 16042 16252 16753 17159 17863 19383 22051 28000 40594 65290 103871 152122 180218 164144 121022 95424 67768 36537 22702 18967 17845 16913 15952 15720 15372 15078 14861 14896 14789 14582 14478 14709 14578 14488 14610 14324 14289 14433 14163 14309 14243 14003 14116 14068 14045 14091 14028 14124 14192 14098 14150 13797 14056 14177 13963 13927 14040 13895 14002 14179 13995 14002 13860 13633 13592 13703 13770 13513 13642 13389 13572 13276 13181 13553 13199 13160 13455 13515 13309 13128 13107 13217 13239 13299 13198 13260 13409 13420 13249 13339 13288 13367 13455 13484 13181 13120 13340 13304 13313 13487 13272 13480 13221 13370 13004 12990 12994 13153 13201 13064 13243 13226 13017 13115 13046 13048 13020 13128 13029 13017 13089 12745 13002 13042 12880 12650 12657 12909 12993 12960 12875 12987 12873 12806 12665 12681 13096 12813 12750 12655 12656 12645 12651 12695 12655 12862 12536 12617 12627 12686 12485 12582 12954 12833 12727 12603 12781 12721 12443 12790 12566 12474 12414 12611 12643 12656 12680 12613 12446 12655 12572 12422 12688 12390 12451 12604 12683 12441 12267 12547 12486 12407 12420 12599 12386 12507 12984 13016 13689 14701 15822 15997 14843 14035 14228 13526 12625 12354 12459 12259 12557 12395 12502 12528 12425 12431 12356 12419 12507 12153 12412 12209 12318 12198 12317 12296 12160 12066 12384 12201 12216 12079 12293 12298 12008 12523 12239 12304 12497 12353 12159 11977 12220 12216 12089 12315 12192 12271 12284 12197 12156 11906 12101 12136 12044 12108 12190 12217 12312 12083 12146 12297 12229 12212 12221 12129 12064 12308 12263 12068 12324 12161 12272 12082 12176 12283 12166 12042 11991 11965 11995 12038 11857 12166 11998 12172 12207 12028 12056 12076 12033 12080 12058 11981 12157 11976 11750 12219 12036 11971 11855 11788 12056 12092 11973 12128 11958 12099 12038 12070 12073 12099 11910 12081 11789 12063 11928 12095 11882 12021 12007 12301 12286 12054 12095 11937 12082 12176 11832 11942 11876 12087 11999 12156 11891 11922 11989 11887 12187 11903 11726 12056 11907 11912 11976 12029 12171 11760 11886 12057 11920 11913 11888 12097 11895 11941 11939 11800 12125 11929 11908 12076 11859 11906 12048 11993 11928 11989 12091 12130 12008 12104 11960 12203 12046 11930 12093 12036 12034 12022 11975 12210 11965 11990 11977 12105 12208 12230 11862 11934 12054 12057 11940 12047 11956 12103 11870 11930 11984 11903 11942 12036 11935 12120 12083 11673 12093 12164 11954 11792 12260 11840 11824 11888 11834 11870 11766 11944 12040 11851 11884 11864 11857 11913 12003 11953 11999 11902 12105 12041 11996 12001 11986 12383 11966 12068 12308 11901 11930 11917 12044 12068 12112 11912 11934 12067 12104 12229 11951 11948 11980 11762 12035 11906 11894 11751 12057 11852 11848 11960 12008 11780 11969 12114 11937 12010 11904 11817 11823 12035 11850 12103 11992 11959 12122 11866 12185 11937 12223 11929 11942 12040 11798 11998 12298 12011 12248 11998 11892 11863 11962 11968 11986 11922 12018 12032 11914 12090 11890 12009 12115 12113 12496 12684 13160 13664 13548 12791 12560 12750 12552 12508 12382 12124 12007 12160 11906 11897 11729 12071 12162 11743 11946 12055 11906 12006 11803 12119 11940 12110 11822 11983 11993 12242 12127 12175 11942 12114 12090 12067 12184 12061 12234 12206 12138 12155 12063 12434 12244 12268 12228 12364 12286 12044 12416 12160 12259 12256 12214 12055 12264 12122 12548 12205 12074 12198 12257 12434 12007 12332 12245 12342 12290 12125 12215 12157 12308 12225 12421 12619 12358 12380 12175 12289 12117 12183 12267 12220 12500 12266 12154 12603 12534 12407 12577 13148 13031 13633 13685 14426 14803 15326 16510 19859 26674 40033 63743 93352 97540 66824 45911 50055 57063 46665 27352 17898 15328 14477 13833 13305 13198 12903 12595 12647 12870 12334 12445 12585 12262 12342 12303 12363 12292 12225 12360 12329 12198 12469 12213 12192 12286 12124 12029 12133 12248 12097 12156 12321 12045 11990 11965 12250 12276 12127 11973 12407 11943 12086 11975 11859 12295 12000 12018 12128 12217 12266 12115 12360 12162 12062 12091 12280 12136 12057 11728 12046 11811 11718 11817 12264 12019 11959 12090 12080 11936 12076 11845 12011 12155 12034 12181 12113 12037 12084 12017 11790 12022 12072 11834 12149 12226 12365 12314 12298 12402 12288 12241 12269 11995 12279 12316 11991 11990 12127 12349 12293 12299 12324 12313 11982 12322 12399 12328 11920 12273 12194 12187 12290 12105 12179 12070 12044 12153 12325 12280 12417 12336 12320 12547 12380 12257 12325 12423 12155 12639 12173 12399 12481 12489 12292 12213 12523 12351 12476 12982 12975 13375 14088 13991 14751 15034 15636 16175 17631 22094 31691 49512 81327 117244 115293 71774 46822 53043 66515 63168 39238 22173 16894 15156 14319 13813 13484 13319 13017 12731 12797 12446 12497 12545 12580 12302 12411 12348 12223 12132 12324 12154 11985 12393 12007 12222 12189 12113 12227 12383 12035 12042 12323 12257 12174 12159 12009 12025 12193 12008 11972 11994 12085 11846 11981 12069 12062 11949 12147 12153 11972 11714 11863 11932 11973 12123 11991 11960 12077 11861 11913 11691 11896 11846 11880 12084 11960 11876 11903 12061 11770 11915 12247 12266 12178 12200 12464 12522 12574 12735 13080 14295 16022 20283 26223 31278 27994 20355 17345 18881 21647 20447 16387 13558 12835 12367 12306 11893 12003 12128 11971 12126 11918 11733 11854 11946 11956 11875 11805 11735 11889 11782 11947 12088 12083 12107 11972 11977 11880 11925 11983 11695 11999 11809 11990 11735 12011 12095 11943 11750 11852 11993 11823 11659 11671 11968 11790 11813 11946 11799 11753 11800 11828 11746 12018 12022 11762 11655 11887 11744 11787 11894 11825 11822 11702 11923 11961 11741 11828 11818 11679 11817 12003 11689 11732 11952 11824 11707 11813 11798 11735 11618 11648 11778 11722 11634 11679 11580 11954 11628 11519 11745 11853 11760 11938 11595 11650 11822 11673 12125 11814 11483 11830 11607 11766 11631 11830 11726 11600 11506 11626 11774 11752 11636 11787 11759 11665 11810 11699 11723 11827 11663 11775 11960 11884 11728 11718 11735 11865 12067 11894 12128 12181 12180 11936 12380 12327 13045 14225 16509 21002 26263 26426 20468 16041 15473 17743 19506 18548 15038 13097 12557 12173 12039 12056 11970 11858 11710 11749 11820 11777 12148 11774 11860 11945 11686 11763 11927 11935 12062 11775 12116 12108 11995 12006 11802 11796 11818 11875 11976 11974 11818 12106 12042 11824 11863 12028 11919 11993 11768 11976 12073 11957 11840 12077 11693 11837 11695 12050 12036 11698 11773 11968 11930 11798 12037 11971 11902 11921 12069 11950 11832 12363 12414 12378 12612 12807 12960 13031 13118 13482 14119 16060 19937 27038 39318 50250 43984 27556 20343 21740 26668 31238 27821 19516 14941 13433 12855 12698 12632 12839 12680 12762 13096 12905 13197 13230 13402 14208 15745 18575 24325 35161 53376 63387 48969 28835 22585 25237 33030 37561 30976 20362 15138 13643 13192 12917 12352 12246 11941 12053 12071 12059 11876 11841 11963 11915 12051 11967 11767 11910 11645 11603 11822 11849 11853 11566 11712 11823 11618 11578 11699 11876 11781 11585 11700 11626 11610 11670 11661 11495 11575 11779 11496 11857 11703 11747 11851 11910 11422 11678 11641 11741 11603 11558 11512 11613 11718 11597 11641 11395 11650 11637 11616 11574 11384 11416 11564 11495 11646 11579 11708 11620 11466 11659 11617 11360 11549 11506 11625 11405 11626 11608 11454 11365 11449 11450 11476 11468 11607 11444 11567 11745 11397 11724 11631 11760 11979 12101 12608 13584 14984 17471 18605 16073 13709 12906 13180 13990 15206 14585 13018 12080 11842 11713 11719 11599 11617 11777 11479 11542 11343 11252 11469 11485 11563 11629 11583 11584 11219 11364 11407 11544 11634 11253 11484 11282 11427 11189 11340 11125 11387 11422 11419 11482 11409 11229 11498 11412 11492 11329 11365 11355 11537 11477 11635 11288 11251 11495 11563 11361 11284 11414 11425 11642 11865 11543 11339 11482 11702 11503 11614 11852 11978 11667 11746 12194 12209 12705 13911 16228 20435 25436 25833 19948 15060 13966 14918 16942 19218 17913 14463 12689 11957 11855 11622 11648 11740 11602 11417 11373 11558 11381 11470 11238 11516 11275 11330 11231 11392 11216 11616 11328 11371 11623 11418 11625 11430 11284 11300 11095 11457 11191 11486 11360 11355 11481 11248 11322 11532 11515 11398 11293 11533 11265 11308 11421 11136 11307 11279 11375 11318 11145 11188 11314 11242 11334 11182 11225 11376 11331 11340 11261 11229 11479 11517 11330 11294 11115 11439 11131 11133 11424 11283 11332 11216 11161 11159 11474 11224 11436 11126 11396 11105 11249 11150 11246 11261 11280 11146 11438 11263 11315 11250 11282 11410 11260 11354 11396 11452 11409 11394 11060 11299 11507 11508 11339 11321 11552 11338 11282 11462 11436 11406 11419 11361 11393 11627 11692 12064 12574 13388 14608 14193 12777 11934 11878 11950 12546 12683 12661 12151 11748 11431 11709 11295 11304 11262 11361 11183 11141 11154 11147 11431 11233 11008 11374 11271 11486 11370 11231 11252 11380 11174 11401 11258 11479 11274 11252 11366 11529 11386 11421 11626 11262 11556 11419 11438 11322 11167 11363 11487 11302 11122 11307 11301 11412 11436 11592 11221 11423 11589 11462 11548 11630 12210 11787 12194 12026 12361 12344 12225 12701 13404 15002 17791 23853 34781 48755 50052 33629 20794 17349 18065 22012 27960 31597 26476 18411 14043 13005 12481 12203 12106 11652 11891 11790 11956 11782 11559 11414 11499 11419 11403 11323 11324 11113 11273 11236 11457 11355 11379 11239 11448 11136 11570 11252 11237 11385 11280 11253 11191 11226 11349 11415 11430 11137 11290 11387 11408 11385 11407 11278 11305 11217 11456 11253 11162 11212 11217 11142 11383 11200 11269 11270 11392 11123 11142 11014 11419 11344 11197 11234 11230 11314 11290 11332 11245 11280 11219 11296 11126 11276 10978 11471 11284 11370 11248 11196 11248 11102 11259 11319 11374 11107 11282 11274 11290 11290 11168 11366 11251 11220 11317 11323 11237 11227 11385 11086 11228 11071 11575 11384 11517 11529 11611 11552 11663 11483 12254 13032 14696 17559 20808 20379 16165 13461 12560 12709 13335 14776 16247 15701 13537 12348 11659 11560 11480 11368 11348 11312 11241 11168 11249 11358 11051 11091 11365 11394 11193 11101 11256 11148 11403 10915 11301 11216 11173 11370 11069 11193 11227 10987 11076 11118 11114 11308 11125 11275 10877 11178 11278 11224 11023 10902 10847 11159 11091 11232 11072 11145 11247 11078 11152 11179 11308 11123 11137 11070 11182 11409 11221 11033 11116 11216 11297 11050 11237 11355 11121 10987 11127 11268 11202 11345 11164 11244 11273 10908 11046 11310 11085 11242 10901 11195 11186 11099 11168 11150 10995 10927 11336 11467 11141 10890 11033 11173 11103 11124 11074 11104 11170 11413 11174 11114 11134 11320 11068 11373 11232 10996 11153 11000 11229 10915 10951 11162 11249 11148 11224 11202 11145 11343 10927 11162 11174 11003 10987 10874 11064 10898 10921 10989 10892 11173 10945 11129 11216 11137 10963 11157 10984 11003 10982 11102 10815 11119 10853 11078 11191 11152 11163 10940 11179 10897 10851 11212 10965 10933 11338 10937 11160 11129 11156 11010 11143 11156 11165 10901 11004 10920 11201 11101 11043 10948 11307 11020 10972 11234 11072 11109 11074 10955 11154 11187 11498 11839 12375 13304 13405 12404 11514 11326 11256 11233 11587 11962 12106 12236 11725 11145 11245 10904 11032 10875 10941 11265 11104 11010 11141 10936 10994 11280 10938 11138 11082 11067 10997 11002 10983 10856 10952 10929 11133 10965 10976 11030 10973 11098 10946 11227 11000 11055 10894 11121 10858 10968 10861 11129 11118 11213 11011 11112 11094 11208 11220 11050 11111 11232 11243 11288 11302 11204 11308 11467 11613 11837 12701 14256 17093 20651 21585 17809 14243 12441 12386 12468 13138 14309 15920 16090 14645 12725 12017 11768 11717 11571 11881 11714 11744 12255 13486 15547 19201 23960 24892 19280 14568 12878 12685 12704 13590 15463 17686 17610 15489 13050 11911 11372 11417 11151 11470 11185 11189 10899 11235 11060 10859 11024 11203 11122 11202 11092 11203 10991 11079 11140 11085 11029 10932 10967 11168 11112 10983 11054 11112 10997 10962 11116 11161 11022 10935 10917 10721 10939 10900 11052 10921 11039 10908 11034 10974 11062 11129 11171 10973 11081 11074 11038 11030 11198 11056 10885 11183 10960 10986 10790 10843 10987 11169 11023 11184 10932 11111 11041 11324 10988 10926 11033 11136 11186 11152 11208 11245 11586 11688 12195 13067 15047 18058 19323 16690 13440 12358 11903 11941 12136 12569 13829 14886 14584 13026 11816 11541 11250 11483 11136 10853 11113 11076 10913 11030 10997 10944 10931 11011 11091 11032 10873 10907 10784 10895 10956 11018 10833 11061 10985 11040 11098 10941 10710 10884 10811 10999 11046 10702 11014 10988 11041 10834 11043 11289 11055 11070 11106 11129 10969 10977 10981 11106 11306 10972 11381 11176 11055 11140 11264 11722 12043 13095 14853 15568 14275 12353 11739 11437 11559 11390 11721 12372 13189 13265 12318 11667 11153 10966 11148 11094 11064 10851 11149 10689 11069 11194 11082 11176 11229 10868 10984 11165 11016 10956 10805 11136 10839 11186 10863 11102 10771 10916 10942 10861 10917 10868 10885 10804 11067 11050 10945 10935 11128 10921 10875 10953 11033 10936 10832 10926 10844 10859 10752 10884 10878 10776 10988 10862 10883 10939 10816 10876 10854 10861 10800 10747 11069 10926 10848 10810 10838 10953 11005 10765 10761 10849 10676 10923 10831 11235 10989 11054 10775 10918 10878 11033 10660 10872 10829 10973 10852 11121 10661 10907 11196 11000 10889 10965 10917 11085 10986 10981 10780 10977 10920 10992 11153 11327 11755 12209 12803 13199 12557 11759 11338 11217 11267 11131 11233 11477 11773 12235 12068 11548 11164 11183 11079 10989 10714 11074 10891 10983 10837 10952 11046 11109 10762 10886 10789 10934 10835 10867 10880 11064 10848 10993 10774 10921 10895 11052 10959 10981 11088 11042 10902 10817 10813 10876 10874 10896 10894 10946 11227 10978 11025 11067 11054 10976 11132 11212 11100 11123 11146 11286 11391 11444 11692 11858 13264 14720 17965 20649 19577 15855 13227 12298 11909 11879 11832 12436 13505 14805 15699 14662 12620 11756 11253 11227 11487 11027 11228 11083 11208 10950 11196 11049 10692 11058 11030 10988 11012 10979 10782 10895 11140 10792 10967 10941 10853 11039 10888 11082 10969 10961 10986 10945 10918 10921 10831 11010 10939 11038 10810 11013 11004 10997 10700 10763 10833 10943 10996 10860 11010 10899 10936 10956 10945 10888 10887 10865 10920 10899 10925 10797 10997 10712 10978 11085 10980 10912 11044 10951 10916 10851 11026 11107 10988 10669 10864 10814 10631 10849 11091 10994 11139 11016 11111 10867 11065 10933 11018 10940 10825 11052 10992 10917 11058 11208 11154 11219 10926 11394 11529 11601 11501 12112 13450 15507 18118 19578 16983 13661 12455 12099 11556 11501 11665 12324 12746 14353 15059 14308 12781 12009 11381 11276 11087 11008 10890 11125 10673 11001 10863 11052 11129 10807 11070 10938 10895 10789 11029 10860 10931 11011 10891 10785 10794 10933 10919 10828 10838 10775 10816 11023 10882 11094 10873 10701 11051 10913 10765 11108 10864 10800 10933 11187 10986 11011 10907 11010 11181 10933 11125 11182 11183 11394 11542 12219 13324 14315 14262 12875 11949 11341 11273 11144 11215 11173 11488 11868 12336 12741 12209 11657 11403 10999 10860 11040 10990 10880 11093 10905 10680 10962 10805 10693 10893 10973 10886 10832 10910 10871 10868 10810 10643 11046 10979 10789 10922 11034 10829 10890 10964 11017 10924 10958 10920 10883 10767 10763 10820 10897 10858 10779 11053 10974 10761 11165 10666 10875 11136 10585 10792 10807 10735 11118 10832 10784 10756 10879 10949 10859 10852 10943 10809 10750 10938 10747 10851 10904 10886 11005 10907 10755 11145 10995 10976 10774 11008 10802 10803 10921 10743 10729 10865 10847 10604 10972 10855 11023 10786 10854 10902 10647 11050 10889 10872 11026 10728 10856 10965 10858 11048 10876 10974 11053 10977 11098 11454 10965 10803 11003 10882 10924 10968 10829 10981 10905 10983 11061 11147 11021 10881 10813 10994 10984 10481 10775 10820 10898 10867 10751 10919 10842 10747 10755 10684 11105 10992 10808 10901 10862 10928 10808 10923 10793 10903 10805 11037 10796 10840 10976 11067 10831 10926 10883 10813 10820 11023 10978 10804 10886 10941 10970 10998 10897 10809 10771 11020 11158 11182 11226 11197 11477 11446 11863 12789 14177 15807 15945 14485 12736 11931 11485 11413 11287 11494 11693 11481 12174 12910 13490 13107 12570 12154 11780 11689 11804 12163 12841 14057 16576 19153 18675 15645 13116 12199 11621 11485 11421 11526 11595 11923 12795 14081 14622 14286 13051 12011 11417 11239 11006 11129 10929 10882 11101 10839 10883 10879 10928 10870 10936 10825 10758 10949 10953 10942 10975 10925 10969 10906 10945 10742 10713 10914 10880 10833 10919 10912 10807 10776 10810 10933 10649 10751 10912 10862 10738 10845 10829 10846 10867 10604 10904 10842 10826 10780 10498 10710 10919 10826 10767 10763 10894 10457 10945 10904 11164 10788 10778 11066 10934 10837 10540 10854 11021 10649 10491 10707 10513 10882 10794 10692 10892 10859 10800 10698 10784 10990 10733 10802 10931 10860 10771 10897 10838 10825 10759 10782 10727 10720 10854 10883 10547 10890 10837 10821 10746 10859 10694 10807 10869 10840 10966 10672 10756 10717 10865 10791 11016 10783 11025 11079 10819 10889 10807 10736 10999 10935 10822 10702 10804 10815 10827 10806 10877 10777 10795 10651 10630 10696 10741 10796 10869 10770 10709 10820 10929 10897 10979 10711 10646 10840 10637 10976 11123 10976 11092 11323 11906 12156 12258 11450 11171 10964 11039 10720 10766 10827 10761 10884 11261 10907 11525 11647 11439 11171 11027 10966 10857 10726 10847 10892 10793 11154 10917 10858 10716 10937 10770 10983 10648 10534 10922 10752 10892 10587 10900 10762 10864 10771 10826 10570 10718 10890 10790 10717 10746 10628 10765 10706 10797 10735 10541 10650 10861 10566 10728 10545 10853 10788 10879 10711 10757 10609 10822 10511 10747 10847 10755 11001 10776 10700 10731 10768 10789 10779 10677 10811 10839 10800 10599 10705 10789 10723 10607 10773 11010 11049 10886 10787 10784 10810 10935 11010 10813 10556 10805 10801 10887 10923 10704 10729 10985 10796 10793 11059 10858 10901 10758 10872 10795 10729 10896 10878 10844 10965 10847 10759 10771 10884 10841 11073 11259 11024 10953 10990 10887 10778 10971 10729 10847 10777 10849 10747 10852 10963 10774 10762 10924 11018 10951 11033 10712 10784 10865 10928 10762 10812 10706 10896 10719 10996 10795 10758 11011 10794 10990 10916 10585 10810 10824 10928 10785 10975 10689 10929 10735 11035 10698 10964 10852 10957 11027 10755 10547 11143 10809 10912 10960 10923 10959 10675 10934 10945 11003 11009 11164 11066 10978 10968 10993 11340 11518 12089 12833 13768 13326 12442 11971 11207 11414 11044 11203 11083 11069 11275 11248 11461 11196 11739 12344 12399 11851 11323 11246 11083 10848 10935 11029 10889 10776 10709 10906 10972 11072 10986 11047 10801 10812 10778 10891 11097 11171 10912 10936 10695 10870 11047 10758 10704 10773 10675 10799 10919 10949 10782 10668 10783 11000 10743 10805 10980 10983 10820 10969 10983 10945 10764 10860 10772 10884 10864 10755 11007 10790 10871 10994 10636 10793 10763 10899 10976 10870 10941 10847 10941 10809 11116 10927 10872 10856 10993 10991 10725 10733 10925 10893 10705 10792 10929 10823 10864 10782 10964 10826 11077 11035 10717 10984 10998 11117 10988 10825 10876 10923 11067 11028 10960 10797 10691 11131 11054 10967 11235 11275 11158 11051 11177 11551 12065 12552 13334 12451 11898 11476 11219 11129 10970 10992 10994 11023 10968 10945 11169 11228 11538 11812 11865 11802 11444 11233 11084 11065 10954 10920 11206 11016 10834 10976 10900 10955 10935 10847 11143 11019 10962 10825 10669 10745 10857 10903 10922 11081 10914 10750 10948 10740 10971 10884 11101 11119 10889 10992 10997 10927 11038 11015 10848 11033 11043 11074 10971 10954 11034 10728 11091 11158 11106 10992 11043 11033 11260 11481 11358 11977 12627 13862 15205 15633 13953 12923 11964 11492 11218 11257 11159 11062 11034 11143 11092 11338 11592 11882 12475 12800 12847 12581 11974 11477 11334 11192 11196 10930 11114 11333 11034 10940 11240 11102 11223 11011 11141 10970 11068 10931 10879 11014 10979 10898 11168 10858 11133 10973 10996 11131 10969 11053 10919 10924 11055 10904 10943 10983 10909 10933 10980 10810 11164 10728 10994 10836 11014 10827 10958 10986 10990 10841 10951 10939 10841 11019 10981 10981 10697 11027 11011 11082 11033 11026 10830 11086 10755 10772 10915 10813 11185 11023 11031 11017 11000 11093 11101 10933 11067 10972 11035 11109 11046 11094 11131 10926 11236 11025 10868 11132 11079 11020 11018 11112 11124 10981 11062 10869 11110 11108 10937 10961 10963 10900 10888 10957 11229 11203 11246 11451 11556 11716 12445 12920 12562 12033 11364 11313 11155 11129 11097 11108 10891 11097 11337 11161 11043 11047 11378 11505 11670 11592 11777 11537 11237 11242 11058 11135 11151 10835 11075 11197 11018 11039 11166 10962 11142 10989 11105 11155 10869 11096 11153 11151 10979 10999 11114 11067 11023 11162 11229 11138 11126 11034 10987 11294 11377 10886 11188 11235 11106 11299 11118 10898 11208 11317 11062 11126 11331 11065 11129 11150 11296 11209 11352 11447 11802 11681 11913 12225 12612 13593 15471 17277 18109 16489 14615 13423 12343 12046 11972 11685 11718</intensities>
			</dataPoints>
		</scan>
	</xrdMeasurement>
</xrdMeasurements>